I'm sorry, but an uncaught exception occurred.

While running game code:
  File "game/ocobniak.rpy", line 54, in script
    scene bg lec osobnak hole:
Exception: Image 'bg lec osobnak' does not accept attributes 'hole'.

-- Full Traceback ------------------------------------------------------------

Full traceback:
  File "game/ocobniak.rpy", line 54, in script
    scene bg lec osobnak hole:
  File "C:\Users\serge\OneDrive\Рабочий стол\renpy-8.3.2-sdk\renpy\ast.py", line 1245, in execute
    show_imspec(self.imspec, atl=getattr(self, "atl", None))
  File "C:\Users\serge\OneDrive\Рабочий стол\renpy-8.3.2-sdk\renpy\ast.py", line 1074, in show_imspec
    renpy.config.show(name,
  File "C:\Users\serge\OneDrive\Рабочий стол\renpy-8.3.2-sdk\renpy\exports\displayexports.py", line 477, in show
    if not base.find_target() and renpy.config.missing_show:
  File "C:\Users\serge\OneDrive\Рабочий стол\renpy-8.3.2-sdk\renpy\display\image.py", line 421, in find_target
    self.target = target._duplicate(a)
  File "C:\Users\serge\OneDrive\Рабочий стол\renpy-8.3.2-sdk\renpy\display\displayable.py", line 249, in _duplicate
    args.extraneous()
  File "C:\Users\serge\OneDrive\Рабочий стол\renpy-8.3.2-sdk\renpy\display\displayable.py", line 109, in extraneous
    raise Exception("Image '{}' does not accept attributes '{}'.".format(
Exception: Image 'bg lec osobnak' does not accept attributes 'hole'.

Windows-10-10.0.19045 AMD64
Ren'Py 8.3.2.24090902
IvanHistory 1.0
Mon Sep 30 20:55:01 2024
